Workbook

Sheet Resumen
D1: REVISIÓN TÉCNICA ELÉCTRICA – INTERVENTORÍA
D2: Instituto Distrital de Deporte y Recreación – IDER
A4: Objeto | B4: Construcción de la Unidad Deportiva de Bayunca, Distrito de Cartagena
A5: Contrato | B5: 1376-2025 Lote 2
A6: Contratista | B6: Consorcio Deport Rev-Bayunca (NIT 902016322-9)
A7: Valor del contrato | B7: 1.3986669e+10
A8: Fecha de inicio / terminación | B8: 26-01-2026 / 26-09-2026
A9: Acta revisada | B9: Mayores y menores cantidades e ítems nuevos (corte 15-10-26)
A10: Interventor eléctrico | B10: [Nombre y matrícula profesional]
A11: Fecha de revisión | B11: 29-10-2026
A14: Resumen por tipo de hallazgo
A15: Tipo | B15: Cantidad
A16: Concordancia | B16: =COUNTIF(Matriz_Observaciones!$E$5:$E$400,A16)
A17: Discrepancia | B17: =COUNTIF(Matriz_Observaciones!$E$5:$E$400,A17)
A18: Incumplimiento normativo | B18: =COUNTIF(Matriz_Observaciones!$E$5:$E$400,A18)
A19: Información faltante | B19: =COUNTIF(Matriz_Observaciones!$E$5:$E$400,A19)
A20: Verificar | B20: =COUNTIF(Matriz_Observaciones!$E$5:$E$400,A20)
A21: Total | B21: =SUM(B16:B20)
A23: Observaciones abiertas por criticidad
A24: Criticidad | B24: Abiertas (no concordancias)
A25: Alta | B25: =COUNTIFS(Matriz_Observaciones!$J$5:$J$400,A25,Matriz_Observaciones!$O$5:$O$400,"<>Cerrada",Matriz_Observaciones!$O$5:$O$400,"<>No aplica",Matriz_Observaciones!$E$5:$E$400,"<>Concordancia")
A26: Media | B26: =COUNTIFS(Matriz_Observaciones!$J$5:$J$400,A26,Matriz_Observaciones!$O$5:$O$400,"<>Cerrada",Matriz_Observaciones!$O$5:$O$400,"<>No aplica",Matriz_Observaciones!$E$5:$E$400,"<>Concordancia")
A27: Baja | B27: =COUNTIFS(Matriz_Observaciones!$J$5:$J$400,A27,Matriz_Observaciones!$O$5:$O$400,"<>Cerrada",Matriz_Observaciones!$O$5:$O$400,"<>No aplica",Matriz_Observaciones!$E$5:$E$400,"<>Concordancia")
A29: Resumen por estado
A30: Estado | B30: Cantidad
A31: Abierta | B31: =COUNTIF(Matriz_Observaciones!$O$5:$O$400,A31)
A32: Respondida | B32: =COUNTIF(Matriz_Observaciones!$O$5:$O$400,A32)
A33: En revisión | B33: =COUNTIF(Matriz_Observaciones!$O$5:$O$400,A33)
A34: Cerrada | B34: =COUNTIF(Matriz_Observaciones!$O$5:$O$400,A34)
A35: No aplica | B35: =COUNTIF(Matriz_Observaciones!$O$5:$O$400,A35)
A37: Valor no sustentado estimado (COP) | B37: =SUM(Matriz_Observaciones!K5:K400)
A38: Suma de las observaciones con valor. Es una estimación conservadora y no incluye sobreprecios sin cuantificar ni ítems faltantes.
A40: Contenido del libro
A41: Items_Electricos | B41: Ítems eléctricos del acta con revisión por ítem e ítems faltantes (hoja prioritaria)
A42: Matriz_Observaciones | B42: Hallazgos con norma, criticidad, acción exigida y seguimiento
A43: Balance_Cantidades | B43: Cantidades del acta vs planos / cálculo / unifilar y valor no sustentado
A44: Regulacion_Recalculada | B44: Caída de tensión recalculada con parámetros editables
A45: Lista_Verificacion | B45: Formato reutilizable de revisión de proyectos eléctricos
A46: Formato_Blanco | B46: Matriz vacía para un nuevo proyecto
A47: Documentos | B47: Control de documentos revisados y pendientes
...

Sheet Items_Electricos
D1: Ítems eléctricos del acta y su revisión
D2: Acta de mayores y menores cantidades (corte 15-10-26). Amarillo = referencia editable. Los ítems NUEVO-xx son necesarios y no están en el acta.
A4: Ítem | B4: Grupo | C4: Descripción (acta) | D4: Und | E4: Cant. contrato | F4: Valor unitario (COP) | G4: Valor contrato (COP) | H4: Var. | I4: Cant. actualizada (acta) | J4: Valor actualizado (COP) | K4: Cant. referencia interventoría | L4: Diferencia (acta − ref.) | M4: Valor no sustentado (COP) | N4: Faltante valorizado (COP) | O4: Estado | P4: Documento soporte | Q4: Observación de la interventoría | R4: Acción exigida | S4: ID matriz | T4: Cant. ajustada validada (supervisor) | U4: Valor total ajustado (COP) | V4: Variación vs. acta (COP) | W4: Validación
A5: CAPÍTULO 1 – PRELIMINARES (relacionados)
A6: 1.4 | B6: Cap 1 | C6: Desmonte de postes electricos existentes. | D6: UND | E6: 9 | F6: 1228405.2 | G6: =E6*F6 | H6: (-) | I6: 0 | J6: =I6*N(F6) | O6: Verificar | P6: DXF | Q6: El DXF muestra 6 postes existentes de 11 m con cruceta; el acta pasa el desmonte de 9 a 0. | R6: Aclarar qué postes se retiran, reubican o conservan. | S6: OBS-021 | T6: =I6 | U6: =T6*N(F6) | V6: =U6-J6 | W6: Pendiente
C7: Subtotal Cap. 1 (eléctricos relacionados) | G7: =SUM(G6:G6) | J7: =SUM(J6:J6) | M7: =SUM(M6:M6) | N7: =SUM(N6:N6) | U7: =SUM(U6:U6) | V7: =SUM(V6:V6)
A8: CAPÍTULO 4 – INSTALACIONES ELÉCTRICAS
A9: 4.1 | B9: Cap 4 | C9: Adecuacion punto de conexión. | D9: UND | E9: 1 | F9: 4029892.8 | G9: =E9*F9 | H9: (=) | I9: 1 | J9: =I9*N(F9) | O9: Verificar | P9: Unifilar | Q9: Punto de conexión de Afinia con tramo, circuito y subestación "PENDIENTE". | R9: Entregar factibilidad aprobada con punto de conexión definido. | S9: OBS-039 | T9: =I9 | U9: =T9*N(F9) | V9: =U9-J9 | W9: Pendiente
A10: 4.2 | B10: Cap 4 | C10: Armado red MT doble terminal MT325. | D10: UND | E10: 1 | F10: 5154192.8 | G10: =E10*F10 | H10: (+) | I10: 2 | J10: =I10*N(F10) | O10: Verificar | P10: Unifilar | Q10: El acta pasa de 1 a 2 armados doble terminal. El unifilar no identifica armados en EPP005 ni EPP007. | R10: Plano de red MT con armados por apoyo. | S10: OBS-065 | T10: =I10 | U10: =T10*N(F10) | V10: =U10-J10 | W10: Pendiente
A11: 4.3 | B11: Cap 4 | C11: Armado red MT fin de linea MT321. | D11: UND | E11: 1 | F11: 2750856.9 | G11: =E11*F11 | H11: (=) | I11: 1 | J11: =I11*N(F11) | O11: Concuerda | P11: Unifilar | Q11: Un fin de línea (EPP007) coincide con el unifilar. | R11: — | T11: =I11 | U11: =T11*N(F11) | V11: =U11-J11 | W11: Validada
A12: 4.4 | B12: Cap 4 | C12: Suministro e instalacion de red monofasica 2H ACSR 1/0 XLPE ecologico. | D12: M | E12: 45 | F12: 85482.72 | G12: =E12*F12 | H12: (+) | I12: 137 | J12: =I12*N(F12) | O12: Discrepa | P12: Unifilar | Q12: Acta: ACSR 1/0 XLPE 2H, 137 m. Unifilar: conductor 123,3 AAAC con vano sin acotar. | R12: Unificar conductor y acotar vanos. | S12: OBS-042 | T12: =I12 | U12: =T12*N(F12) | V12: =U12-J12 | W12: Pendiente
A13: 4.5 | B13: Cap 4 | C13: Suministro e instalacion de poste de concreto de 12x1050kg, incluye transporte, hincado, aplomado y cimentación. | D13: UND | E13: 1 | F13: 7109157 | G13: =E13*F13 | H13: (-) | I13: 0 | J13: =I13*N(F13) | O13: Ítem faltante | P13: Unifilar | Q13: Poste de concreto retirado (1→0), pero el unifilar exige el apoyo EPP007 para transformador, protecciones y fin de línea. Ver NUEVO-02. | R13: Restituir el ítem o aclarar quién suministra el apoyo. | S13: OBS-041 | T13: =I13 | U13: =T13*N(F13) | V13: =U13-J13 | W13: Pendiente
A14: 4.6 | B14: Cap 4 | C14: Suministro e instalacion de protecciones y herrajes para transformador. | D14: UND | E14: 1 | F14: 4313329.6 | G14: =E14*F14 | H14: (=) | I14: 1 | J14: =I14*N(F14) | O14: Concuerda | P14: Unifilar | Q14: Cortacircuitos 27 kV/100 A, herrajes y protecciones del transformador figuran en el unifilar. Verificar el fusible (3 A frente a 3,8 A nominales). | R14: Confirmar selección del fusible con el operador. | S14: OBS-043 | T14: =I14 | U14: =T14*N(F14) | V14: =U14-J14 | W14: Validada
A15: 4.7 | B15: Cap 4 | C15: Suministro e instalacion de SPT para transformador y red MT. | D15: UND | E15: 2 | F15: 1420642 | G15: =E15*F15 | H15: (=) | I15: 2 | J15: =I15*N(F15) | O15: Concuerda | P15: Unifilar | Q15: Dos SPT (transformador y red MT). | R15: — | S15: OBS-053 | T15: =I15 | U15: =T15*N(F15) | V15: =U15-J15 | W15: Validada
A16: 4.8 | B16: Cap 4 | C16: Suministro e instalacion de retenida MT a tierra. | D16: UND | E16: 1 | F16: 1449753.3 | G16: =E16*F16 | H16: (+) | I16: 2 | J16: =I16*N(F16) | O16: Verificar | P16: Unifilar | Q16: El acta pasa de 1 a 2 retenidas. No se muestran en el unifilar. | R16: Plano de red MT con retenidas. | S16: OBS-065 | T16: =I16 | U16: =T16*N(F16) | V16: =U16-J16 | W16: Pendiente
A17: 4.9 | B17: Cap 4 | C17: Suministro e instalacion de transformador 2F-120/240/13200V 100KVA. | D17: UND | E17: 1 | F17: 50813544 | G17: =E17*F17 | H17: (-) | I17: 0 | J17: =I17*N(F17) | O17: Ítem faltante | P17: Unifilar | Q17: Transformador de 100 kVA retirado (1→0). El unifilar muestra uno tipo poste de 50 kVA y no existe ítem de reemplazo. Ver NUEVO-01. | R17: Crear el ítem o certificar que lo suministra Afinia. | S17: OBS-040 | T17: =I17 | U17: =T17*N(F17) | V17: =U17-J17 | W17: Pendiente
A18: 4.10 | B18: Cap 4 | C18: Excavación manual de zanja 0.60x0.40 m sobre material heterogeneo 0-2 m (rocas 0.35m3) bajo cualquier grado de humedad. | D18: M | E18: 780 | F18: 91497.507 | G18: =E18*F18 | H18: (+) | I18: 792 | J18: =I18*N(F18) | O18: Verificar | P18: DXF | Q18: Excavación de 792 m. IN14 está titulado "canalizaciones y excavación" y suma 1.028 m de bancos de ducto: posible duplicidad. Valor en riesgo junto con 4.11: $132,1 M. | R18: APU de IN14.4–6 y plano de zanjas. | S18: OBS-056 | T18: =I18 | U18: =T18*N(F18) | V18: =U18-J18 | W18: Pendiente
A19: 4.11 | B19: Cap 4 | C19: Relleno de zanja de 0.60x0.40 m con material de sitio, incluye riego y compactación. | D19: M | E19: 780 | F19: 75316.042 | G19: =E19*F19 | H19: (+) | I19: 792 | J19: =I19*N(F19) | O19: Verificar | P19: DXF | Q19: Relleno de zanja de 792 m. Posible duplicidad con IN14.4–6 (ver 4.10). | R19: Igual que 4.10. | S19: OBS-056 | T19: =I19 | U19: =T19*N(F19) | V19: =U19-J19 | W19: Pendiente
A20: 4.12 | B20: Cap 4 | C20: Bajante en tuberia IMC 3", incluye capacete y accesorios. | D20: M | E20: 6 | F20: 558577.52 | G20: =E20*F20 | H20: (+) | I20: 10 | J20: =I20*N(F20) | O20: Verificar | P20: Unifilar | Q20: El acta pasa de 6 a 10 m de bajante IMC 3". Son dos tubos, deben ser 6 metros | R20: Detalle de bajantes MT. | S20: OBS-065 | T20: 6 | U20: =T20*N(F20) | V20: =U20-J20 | W20: Validada
A21: 4.13 | B21: Cap 4 | C21: Banco de ducto 2" PVC conduit + reserva 2". | D21: M | E21: 269 | F21: 57462.648 | G21: =E21*F21 | H21: (-) | I21: 20 | J21: =I21*N(F21) | O21: Retirado / reemplazado | P21: Acta | Q21: Reducido de 269 a 20 m; los bancos de ducto se reponen en IN14.4–6. | R21: — | S21: OBS-064 | T21: =I21 | U21: =T21*N(F21) | V21: =U21-J21 | W21: Validada
A22: 4.14 | B22: Cap 4 | C22: Banco de ducto 1" PVC conduit + reserva 3/4" PVC. | D22: M | E22: 435 | F22: 36491.438 | G22: =E22*F22 | H22: (-) | I22: 0 | J22: =I22*N(F22) | O22: Retirado / reemplazado | P22: Acta | Q22: Retirado (435→0); se repone en IN14.4–6. | R22: — | S22: OBS-064 | T22: =I22 | U22: =T22*N(F22) | V22: =U22-J22 | W22: Validada
A23: 4.15 | B23: Cap 4 | C23: Acometida en 2(3x250 MCM THHN/THWN Cu)+1 No.2T Cu. | D23: M | E23: 25 | F23: 1319832.6 | G23: =E23*F23 | H23: (-) | I23: 0 | J23: =I23*N(F23) | O23: Retirado / reemplazado | P23: Acta | Q23: Reemplazado por IN14.7 (2×350 MCM Al). | R23: — | T23: =I23 | U23: =T23*N(F23) | V23: =U23-J23 | W23: Validada
A24: 4.16 | B24: Cap 4 | C24: Acometida en 2No.1/0 Serie 8000+1No.2T Cu desnudo. | D24: M | E24: 458 | F24: 151557.04 | G24: =E24*F24 | H24: (-) | I24: 0 | J24: =I24*N(F24) | O24: Retirado / reemplazado | P24: Acta | Q24: Reemplazado por IN14.10 e IN14.11 (aluminio). | R24: — | T24: =I24 | U24: =T24*N(F24) | V24: =U24-J24 | W24: Validada
A25: 4.17 | B25: Cap 4 | C25: Acometida en 3No.2 Serie 8000+1No.4T Cu. | D25: M | E25: 50 | F25: 130097.37 | G25: =E25*F25 | H25: (-) | I25: 0 | J25: =I25*N(F25) | O25: Retirado / reemplazado | P25: Acta | Q25: Reemplazado por IN14.8 e IN14.9. | R25: — | T25: =I25 | U25: =T25*N(F25) | V25: =U25-J25 | W25: Validada
A26: 4.18 | B26: Cap 4 | C26: Ramal en 2No.10+1No.12 Cu THHN/THWN. | D26: M | E26: 479 | F26: 40660.218 | G26: =E26*F26 | H26: (+) | I26: 528 | J26: =I26*N(F26) | O26: Verificar | P26: Ninguno | Q26: Ramal de 528 m (+49 m). No hay plano de instalaciones interiores. | R26: Plano de instalaciones interiores con recorridos. | S26: OBS-006 | T26: =I26 | U26: =T26*N(F26) | V26: =U26-J26 | W26: Pendiente
A27: 4.19 | B27: Cap 4 | C27: Ramal en 3No.12 LH en tuberia 3/4" PVC SCH40 /EMT. | D27: M | E27: 50 | F27: 77089.3 | G27: =E27*F27 | H27: (=) | I27: 50 | J27: =I27*N(F27) | O27: Verificar | P27: Ninguno | Q27: Sin documento de soporte. | R27: Plano de instalaciones interiores. | S27: OBS-006 | T27: =I27 | U27: =T27*N(F27) | V27: =U27-J27 | W27: Pendiente
A28: 4.20 | B28: Cap 4 | C28: Ramal en 3No.12 LH en tuberia 1/2" PVC SCH40 /EMT. | D28: M | E28: 50 | F28: 69193.431 | G28: =E28*F28 | H28: (=) | I28: 50 | J28: =I28*N(F28) | O28: Verificar | P28: Ninguno | Q28: Sin documento de soporte. | R28: Plano de instalaciones interiores. | S28: OBS-006 | T28: =I28 | U28: =T28*N(F28) | V28: =U28-J28 | W28: Pendiente
A29: 4.21 | B29: Cap 4 | C29: Suministro e instalacion de cable encauchetado 3x12 AGW. | D29: M | E29: 270 | F29: 31249.61 | G29: =E29*F29 | H29: (=) | I29: 270 | J29: =I29*N(F29) | O29: Verificar | P29: Ninguno | Q29: Cable encauchetado 3×12 de 270 m sin documento de soporte. | R29: Justificar uso y recorrido. | S29: OBS-006 | T29: =I29 | U29: =T29*N(F29) | V29: =U29-J29 | W29: Pendiente
A30: 4.22 | B30: Cap 4 | C30: Tablero general de iluminación y control de luces según diagrama unifilar. | D30: UND | E30: 1 | F30: 49793792 | G30: =E30*F30 | H30: (=) | I30: 1 | J30: =I30*N(F30) | O30: Concuerda | P30: Unifilar | Q30: Tablero general y control según unifilar (acometida 2×225 A, mástiles, canchas, camerinos y garita). Verificar APU: puede incluir los breakers de IN14.14 e IN14.15. | R30: Presentar APU. | S30: OBS-049 | T30: =I30 | U30: =T30*N(F30) | V30: =U30-J30 | W30: Validada
A31: 4.23 | B31: Cap 4 | C31: Suministro y montaje de tablero bimetalico de 18 circuitos bifasico, barraje min 125A, marquillado de acuerdo a reglamento técnico RETIE. | D31: UND | E31: 1 | F31: 1361693.1 | G31: =E31*F31 | H31: (-) | I31: 0 | J31: =I31*N(F31) | O31: Retirado / reemplazado | P31: Acta | Q31: Tablero de 18 circuitos retirado; se reponen IN14.12 e IN14.13. | R31: — | T31: =I31 | U31: =T31*N(F31) | V31: =U31-J31 | W31: Validada
A32: 4.24 | B32: Cap 4 | C32: Suministro y montaje de tablero de distribucion para sistema de bombeo, incluye totalizador de 2x70A, 2 totalizadores secundarios 2x40A, gabinete en lamina cold roled, pintura electrostatica. | D32: UND | E32: 1 | F32: 11196490 | G32: =E32*F32 | H32: (-) | I32: 0 | J32: =I32*N(F32) | O32: Retirado / reemplazado | P32: Acta | Q32: Tablero de bombeo retirado. | R32: — | T32: =I32 | U32: =T32*N(F32) | V32: =U32-J32 | W32: Validada
A33: 4.25 | B33: Cap 4 | C33: Suministro e instalacion de caja de abonado 8P para conexionado de luminarias. | D33: UND | E33: 4 | F33: 1207695.1 | G33: =E33*F33 | H33: (+) | I33: 10 | J33: =I33*N(F33) | K33: =Balance_Cantidades!H13 | L33: =I33-K33 | M33: =MAX(0,L33)*N(F33) | N33: =MAX(0,-L33)*N(F33) | O33: Discrepa | P33: Planos | Q33: Acta: 10. Criterio de la interventoría: 12 (4 mástiles + 8 postes). Deberian ser 12 (resolver los dos postes de la multiple) | R33: Ajustar a 12 si se confirman 8 postes de 12 m. | S33: OBS-016 | T33: 12 | U33: =T33*N(F33) | V33: =U33-J33 | W33: Validada
A34: 4.26 | B34: Cap 4 | C34: Suministro e instalacion de breaker enchufable 20A. | D34: UND | E34: 15 | F34: 42000.879 | G34: =E34*F34 | H34: (-) | I34: 10 | J34: =I34*N(F34) | O34: Verificar | P34: Unifilar | Q34: El tablero general solo usa 2 × 20 A (Fútbol 6 y Múltiple). El resto sería para tableros internos no entregados. | R34: Cuadros de carga de tableros internos. | S34: OBS-006 | T34: =I34 | U34: =T34*N(F34) | V34: =U34-J34 | W34: Pendiente
A35: 4.27 | B35: Cap 4 | C35: Suministro e instalacion de breaker enchufable 2x20A. | D35: UND | E35: 3 | F35: 108722.14 | G35: =E35*F35 | H35: (+) | I35: 6 | J35: =I35*N(F35) | O35: Verificar | P35: Unifilar | Q35: Ver 4.26. | R35: Cuadros de carga de tableros internos. | S35: OBS-006 | T35: =I35 | U35: =T35*N(F35) | V35: =U35-J35 | W35: Pendiente
A36: 4.28 | B36: Cap 4 | C36: Suministro e instalacion de SPT en cable 4/0 cu desnudo, incluye, soldadura cadweld, varilla de puesta a tierra, pletina de puesta a tierra. | D36: UND | E36: 1 | F36: 16714649 | G36: =E36*F36 | H36: (-) | I36: 0 | J36: =I36*N(F36) | O36: Retirado / reemplazado | P36: Acta | Q36: Reemplazado por IN14.16 (malla 5 × 5 m). | R36: — | S36: OBS-053 | T36: =I36 | U36: =T36*N(F36) | V36: =U36-J36 | W36: Validada
A37: 4.29 | B37: Cap 4 | C37: Suministro e instalacion de sistema de apantallamiento para mastiles de iluminacion. | D37: UND | E37: 6 | F37: 6908528.1 | G37: =E37*F37 | H37: (+) | I37: 10 | J37: =I37*N(F37) | K37: =Balance_Cantidades!H12 | L37: =I37-K37 | M37: =MAX(0,L37)*N(F37) | N37: =MAX(0,-L37)*N(F37) | O37: Discrepa | P37: Planos | Q37: Acta: 10. Referencia 8 (4 mástiles + 4 postes de la tabla); sería 12 si se aceptan 8 postes de 12 m. Falta evaluación de riesgo por rayos. SOLO SE REQUIEREN PARA LOS MASTILES DE FUTBOL 11/9, ES DECIR 4 UNIDADES | R37: Entregar evaluación de riesgo por rayos. | S37: OBS-015 | T37: 4 | U37: =T37*N(F37) | V37: =U37-J37 | W37: Validada
A38: 4.30 | B38: Cap 4 | C38: Salida para iluminacion en tuberia PVC SCH40/EMT 1/2", cable No.12 LSHF, incluye accesorios. | D38: UND | E38: 87 | F38: 396961.63 | G38: =E38*F38 | H38: (-) | I38: 45 | J38: =I38*N(F38) | K38: 45 | L38: =I38-K38 | M38: =MAX(0,L38)*N(F38) | N38: =MAX(0,-L38)*N(F38) | O38: Concuerda | P38: DXF | Q38: DXF: 7 ojos de buey + 6 herméticas LED + 32 herméticas 2×18 = 45. | R38: — | S38: OBS-059 | T38: =I38 | U38: =T38*N(F38) | V38: =U38-J38 | W38: Validada
A39: 4.31 | B39: Cap 4 | C39: Salida para iluminacion de emergencia en tuberia PVC SCH40/EMT 1/2", cable No.12 LSHF, incluye accesorios. | D39: UND | E39: 18 | F39: 424182.76 | G39: =E39*F39 | H39: (-) | I39: 5 | J39: =I39*N(F39) | K39: 5 | L39: =I39-K39 | M39: =MAX(0,L39)*N(F39) | N39: =MAX(0,-L39)*N(F39) | O39: Concuerda | P39: DXF | Q39: DXF: 5 luminarias de emergencia. | R39: — | S39: OBS-059 | T39: =I39 | U39: =T39*N(F39) | V39: =U39-J39 | W39: Validada
A40: 4.32 | B40: Cap 4 | C40: Salida para interruptor sencillo en tuberia PVC SCH40/EMT 1/2", cable No.12 LSHF , incluye accesorios. | D40: UND | E40: 28 | F40: 411108.72 | G40: =E40*F40 | H40: (-) | I40: 11 | J40: =I40*N(F40) | K40: 11 | L40: =I40-K40 | M40: =MAX(0,L40)*N(F40) | N40: =MAX(0,-L40)*N(F40) | O40: Concuerda | P40: DXF | Q40: DXF: 11 interruptores sencillos. | R40: — | S40: OBS-059 | T40: =I40 | U40: =T40*N(F40) | V40: =U40-J40 | W40: Validada
A41: 4.33 | B41: Cap 4 | C41: Salida para tomacorriente doble en tuberia PVC SCH40/EMT 1/2", cable No.12 LSHF, incluye accesorios. | D41: UND | E41: 14 | F41: 400977.12 | G41: =E41*F41 | H41: (-) | I41: 13 | J41: =I41*N(F41) | K41: 13 | L41: =I41-K41 | M41: =MAX(0,L41)*N(F41) | N41: =MAX(0,-L41)*N(F41) | O41: Concuerda | P41: DXF | Q41: DXF: 13 tomas normales. | R41: — | S41: OBS-059 | T41: =I41 | U41: =T41*N(F41) | V41: =U41-J41 | W41: Validada
...

Sheet Balance_Cantidades
D1: Balance de cantidades: Excel contratista vs. planos / cálculo / unifilar
D2: Celdas amarillas = cantidad de referencia adoptada por la interventoría (editable). Valor no sustentado = exceso × valor unitario.
A4: Ítem | B4: Descripción | C4: Und | D4: Cant. balance (Excel) | E4: Cant. planos / DXF | F4: Cant. cálculo regulación | G4: Cant. unifilar / informe | H4: Cant. referencia adoptada | I4: Diferencia (balance − ref.) | J4: Valor unitario (COP) | K4: Valor no sustentado (COP) | L4: Criterio de referencia / nota
A5: IN16.18 | B5: Proyectores LED 820 W (Fútbol 9) | C5: UND | D5: 32 | E5: 32 | F5: 32 | H5: 32 | I5: =D5-H5 | J5: 10501556 | K5: =MAX(0,I5)*J5 | L5: Cantidad coincide (4 mástiles × 8). El plano/DXF/cálculo son de 480 W, no 820 W: sobreprecio por referencia aún sin cuantificar.
A6: IN16.19 | B6: Proyectores LED 450 W (Múltiple / Fútbol 6) | C6: UND | D6: 46 | E6: 6 | F6: 18 | H6: 6 | I6: =D6-H6 | J6: 6001021 | K6: =MAX(0,I6)*J6 | L6: Plano e informe DIALux: 6 × 160 W. Cálculo: 6 postes × 3 × 160 W = 18. Ningún documento muestra 450 W. Referencia = plano.
A7: IN14.20 | B7: Mástil 12 m (4 reflectores) | C7: UND | D7: 8 | E7: 4 | F7: 6 | G7: 2 | H7: 4 | I7: =D7-H7 | J7: 26954265 | K7: =MAX(0,I7)*J7 | L7: Plano: tabla = 4, dibujados = 2. Cálculo = 6. Unifilar = 2 circuitos de cancha. Referencia = tabla del plano (ajustar si se adopta otro). Nota: si la interventoría mantiene 12 cajas de abonado (4 mástiles + 8 postes), implicaría 8 postes de 12 m: confirmar y, de aceptarse, cambiar la referencia a 8.
A8: IN14.21 | B8: Mástil 22 m (10 reflectores) | C8: UND | D8: 4 | E8: 4 | F8: 4 | G8: 4 | H8: 4 | I8: =D8-H8 | J8: 57610106 | K8: =MAX(0,I8)*J8 | L8: Cantidad coincide. Diseño = 8 proyectores por mástil; balance dice capacidad 10 al mismo precio del 4.47 (capacidad 8).
A9: S/C | B9: Luminaria solar 60 W | C9: UND | D9: 30 | E9: 0 | F9: 0 | G9: 0 | H9: 0 | I9: =D9-H9 | J9: 3760000 | K9: =MAX(0,I9)*J9 | L9: No aparece en planos, DXF, cálculo ni unifilar. Sin código de ítem; unidad "UMD".
A10: S/C | B10: Poste metálico 5 m para luminaria solar | C10: UND | D10: 30 | E10: 0 | F10: 0 | G10: 0 | H10: 0 | I10: =D10-H10 | J10: 2672789 | K10: =MAX(0,I10)*J10 | L10: Sin respaldo en planos. Sin código de ítem.
A11: 4.44 | B11: Orientación de reflectores deportivos (total 32 + 46) | C11: UND | D11: 78 | E11: 38 | H11: 4 | I11: =D11-H11 | J11: 670209.62 | K11: =MAX(0,I11)*J11 | L11: Referencia = 32 (480 W) + 6 (160 W) = 38. DEBERIAN SOLO SER 4, PARA FUTBOL
A12: 4.29 | B12: Apantallamiento de mástiles de iluminación | C12: UND | D12: 10 | E12: 8 | H12: 4 | I12: =D12-H12 | J12: 6908528.1 | K12: =MAX(0,I12)*J12 | L12: Postes: 4 (22 m) + 4 (12 m, tabla) = 8. Máximo justificable. SOLO SE REQUIEREN PARA LOS MASTILES DE FUTBOL 11/9, ES DECIR 4 UNIDADES
A13: 4.25 | B13: Caja de abonado 8P para luminarias | C13: UND | D13: 10 | E13: 8 | H13: 12 | I13: =D13-H13 | J13: 1207695.1 | K13: =MAX(0,I13)*J13 | L13: Una por poste/mástil: 4 + 4. DEBERIAN SER 12
A14: IN14.11 | B14: Alimentador mástiles Fútbol 9 (2#4 Al + T) | C14: M | D14: 817.2 | E14: 576 | F14: 673 | H14: 673 | I14: =D14-H14 | J14: 141382 | K14: =MAX(0,I14)*J14 | L14: Cálculo: 232+191+105+145 = 673 m (incluye 22 m de altura por mástil). DXF ≈ 576 m (BT-05 sin trazado). REVISAR CANTIDADES EN SITIO
A15: IN14.10 | B15: Alimentador Múltiple y Fútbol 6 (2#6 Al + T) | C15: M | D15: 486.8 | E15: 196 | F15: 408 | H15: 408 | I15: =D15-H15 | J15: 117358 | K15: =MAX(0,I15)*J15 | L15: Cálculo: 6 postes = 408 m. DXF (IE BT-01/02) ≈ 196 m, incompleto. Referencia conservadora = cálculo.
A16: IN14.7 | B16: Acometida transformador–TGD (2×350 MCM Al) | C16: M | D16: 27.6 | F16: 15 | H16: 15 | I16: =D16-H16 | J16: 471887 | K16: =MAX(0,I16)*J16 | L16: Cálculo usa 15 m. Verificar localización real del transformador y del TGD.
A17: IN14.9 | B17: Acometida TB-Garita (2#6 Al) | C17: M | D17: 64.8 | F17: 58 | H17: 58 | I17: =D17-H17 | J17: 134966 | K17: =MAX(0,I17)*J17 | L17: Cálculo: 58 m.
A18: IN14.8 | B18: Acometida TB-Camerinos (2#8 Al) | C18: M | D18: 4.8 | F18: 8 | H18: 8 | I18: =D18-H18 | J18: 115242 | K18: =MAX(0,I18)*J18 | L18: Balance por debajo del cálculo (8 m): déficit, no genera valor no sustentado.
A19: IN14.14 / .15 | B19: Breakers enchufables 2×30 A (2) y 2×40 A (1) | C19: UND | D19: 3 | H19: 0 | I19: =D19-H19 | J19: 205400 | K19: =MAX(0,I19)*J19 | L19: Posible doble cobro con 4.22 (tablero general "según unifilar"). Referencia 0 hasta ver el APU de 4.22. Valor unit. = promedio (400.562+215.638)/3.
A20: S/I | B20: Transformador 50 kVA tipo poste | C20: UND | D20: 0 | G20: 1 | H20: 1 | I20: =D20-H20 | J20: 0 | K20: =MAX(0,I20)*J20 | L20: Unifilar: 50 kVA. Balance: 4.9 (100 kVA) retirado, sin ítem de reemplazo. Déficit: aclarar suministro (¿Afinia?).
A21: S/I | B21: Poste de concreto EPP007 (soporte del transformador) | C21: UND | D21: 0 | G21: 1 | H21: 1 | I21: =D21-H21 | J21: 0 | K21: =MAX(0,I21)*J21 | L21: 4.5 retirado, sin reemplazo. Aclarar.
A22: S/I | B22: DPS (3 en MT, 3 en transformador, 1 en TGD) | C22: UND | D22: 0 | G22: 7 | H22: 7 | I22: =D22-H22 | J22: 0 | K22: =MAX(0,I22)*J22 | L22: No hay ítem de DPS en el balance (solo 4.6 protecciones y herrajes).
J24: TOTAL no sustentado | K24: =SUM(K5:K22)
B26: Nota: la cifra no incluye el posible sobreprecio de los proyectores de 820 W ni el valor de ítems faltantes (transformador, poste, DPS).

Sheet Regulacion_Recalculada
D1: Recalculo de regulación de tensión (circuitos monofásicos 2F, 240 V)
D2: ΔV = 2·L·P / (γ·S·V). Celdas amarillas editables. Con γ = 56 (Cu) se reproduce lo presentado por el contratista.
A4: γ aluminio (m/Ω·mm²) | B4: 35 | D4: Criterio: NTC 2050 210-19 y 215-2 (notas informativas: 3 % alimentador / 5 % total). Confirmar criterio contractual.
A5: γ usado por el contratista | B5: 56
A6: Tensión V | B6: 240
A7: Límite alimentador (%) | B7: 0.03
A8: Límite total (%) | B8: 0.05
A10: Circuito | B10: Carga P (W) | C10: Longitud (m) | D10: Cable (según unifilar) | E10: S usada por contratista (mm²) | F10: S real del cable (mm²) | G10: % contratista (hoja) | H10: ΔV recalculada (V) | I10: % recalculado | J10: Estado alimentador | K10: % total (con transformador) | L10: Estado total | M10: S alterna propuesta (mm²) | N10: % con S alterna | O10: Observación
A11: Transformador → TGD | B11: 45000 | C11: 15 | D11: 2×350 MCM Al | E11: 202 | F11: 177.34 | G11: 0.00207 | H11: =2*C11*B11/($B$4*F11*$B$6) | I11: =H11/$B$6 | J11: =IF(I11>$B$7,"NO CUMPLE","CUMPLE") | K11: =I11 | L11: =IF(K11>$B$8,"NO CUMPLE","CUMPLE") | O11: Contratista usa 202 mm² (350 MCM = 177,34). Carga = capacidad nominal, no carga real.
A12: Mástil 1 | B12: 3840 | C12: 232 | D12: 2#4 Al | E12: 68 | F12: 21.14 | G12: 0.00812 | H12: =2*C12*B12/($B$4*F12*$B$6) | I12: =H12/$B$6 | J12: =IF(I12>$B$7,"NO CUMPLE","CUMPLE") | K12: =I12+$I$11 | L12: =IF(K12>$B$8,"NO CUMPLE","CUMPLE") | M12: 33.62 | N12: =2*C12*B12/($B$4*M12*$B$6)/$B$6 | O12: Contratista usa 68 mm² (≈2/0) en lugar de 21,14.
A13: Mástil 2 | B13: 3840 | C13: 191 | D13: 2#4 Al | E13: 21.14 | F13: 21.14 | G13: 0.02151 | H13: =2*C13*B13/($B$4*F13*$B$6) | I13: =H13/$B$6 | J13: =IF(I13>$B$7,"NO CUMPLE","CUMPLE") | K13: =I13+$I$11 | L13: =IF(K13>$B$8,"NO CUMPLE","CUMPLE") | M13: 33.62 | N13: =2*C13*B13/($B$4*M13*$B$6)/$B$6
A14: Mástil 3 | B14: 3840 | C14: 105 | D14: 2#4 Al | E14: 21.14 | F14: 21.14 | G14: 0.01183 | H14: =2*C14*B14/($B$4*F14*$B$6) | I14: =H14/$B$6 | J14: =IF(I14>$B$7,"NO CUMPLE","CUMPLE") | K14: =I14+$I$11 | L14: =IF(K14>$B$8,"NO CUMPLE","CUMPLE") | M14: 33.62 | N14: =2*C14*B14/($B$4*M14*$B$6)/$B$6
A15: Mástil 4 | B15: 3840 | C15: 145 | D15: 2#4 Al | E15: 21.14 | F15: 21.14 | G15: 0.01633 | H15: =2*C15*B15/($B$4*F15*$B$6) | I15: =H15/$B$6 | J15: =IF(I15>$B$7,"NO CUMPLE","CUMPLE") | K15: =I15+$I$11 | L15: =IF(K15>$B$8,"NO CUMPLE","CUMPLE") | M15: 33.62 | N15: =2*C15*B15/($B$4*M15*$B$6)/$B$6
A16: Poste 12 m 1 | B16: 480 | C16: 64 | D16: 2#6 Al | E16: 13.29 | F16: 13.29 | G16: 0.00143 | H16: =2*C16*B16/($B$4*F16*$B$6) | I16: =H16/$B$6 | J16: =IF(I16>$B$7,"NO CUMPLE","CUMPLE") | K16: =I16+$I$11 | L16: =IF(K16>$B$8,"NO CUMPLE","CUMPLE") | O16: Cálculo tiene 6 postes; unifilar 2 circuitos; plano 2/4.
A17: Poste 12 m 2 | B17: 480 | C17: 53 | D17: 2#6 Al | E17: 13.29 | F17: 13.29 | G17: 0.00119 | H17: =2*C17*B17/($B$4*F17*$B$6) | I17: =H17/$B$6 | J17: =IF(I17>$B$7,"NO CUMPLE","CUMPLE") | K17: =I17+$I$11 | L17: =IF(K17>$B$8,"NO CUMPLE","CUMPLE")
A18: Poste 12 m 3 | B18: 480 | C18: 31 | D18: 2#6 Al | E18: 13.29 | F18: 13.29 | G18: 0.00069 | H18: =2*C18*B18/($B$4*F18*$B$6) | I18: =H18/$B$6 | J18: =IF(I18>$B$7,"NO CUMPLE","CUMPLE") | K18: =I18+$I$11 | L18: =IF(K18>$B$8,"NO CUMPLE","CUMPLE")
A19: Poste 12 m 4 | B19: 480 | C19: 94 | D19: 2#6 Al | E19: 13.29 | F19: 13.29 | G19: 0.00211 | H19: =2*C19*B19/($B$4*F19*$B$6) | I19: =H19/$B$6 | J19: =IF(I19>$B$7,"NO CUMPLE","CUMPLE") | K19: =I19+$I$11 | L19: =IF(K19>$B$8,"NO CUMPLE","CUMPLE")
A20: Poste 12 m 5 | B20: 480 | C20: 113 | D20: 2#6 Al | E20: 13.29 | F20: 13.29 | G20: 0.00253 | H20: =2*C20*B20/($B$4*F20*$B$6) | I20: =H20/$B$6 | J20: =IF(I20>$B$7,"NO CUMPLE","CUMPLE") | K20: =I20+$I$11 | L20: =IF(K20>$B$8,"NO CUMPLE","CUMPLE")
A21: Poste 12 m 6 | B21: 480 | C21: 53 | D21: 2#6 Al | E21: 13.29 | F21: 13.29 | G21: 0.00119 | H21: =2*C21*B21/($B$4*F21*$B$6) | I21: =H21/$B$6 | J21: =IF(I21>$B$7,"NO CUMPLE","CUMPLE") | K21: =I21+$I$11 | L21: =IF(K21>$B$8,"NO CUMPLE","CUMPLE")
A22: TB-Camerinos | B22: 8722 | C22: 8 | D22: 2#8 (Al/Cu?) | E22: 8.36 | F22: 8.36 | G22: 0.00518 | H22: =2*C22*B22/($B$4*F22*$B$6) | I22: =H22/$B$6 | J22: =IF(I22>$B$7,"NO CUMPLE","CUMPLE") | K22: =I22+$I$11 | L22: =IF(K22>$B$8,"NO CUMPLE","CUMPLE") | O22: Corriente 40,4 A > breaker 40 A.
A23: TB-Garita | B23: 5250 | C23: 58 | D23: 2#6 Al | E23: 13.29 | F23: 13.29 | G23: 0.01421 | H23: =2*C23*B23/($B$4*F23*$B$6) | I23: =H23/$B$6 | J23: =IF(I23>$B$7,"NO CUMPLE","CUMPLE") | K23: =I23+$I$11 | L23: =IF(K23>$B$8,"NO CUMPLE","CUMPLE")

Sheet Matriz_Observaciones
D1: Matriz de observaciones de la revisión eléctrica
D2: Proyecto: Unidad Deportiva de Bayunca – Contrato 1376-2025 Lote 2. Columnas amarillas: seguimiento (contratista / interventoría).
A4: ID | B4: Área | C4: Documento(s) fuente | D4: Ref. (ítem / plano / hoja) | E4: Tipo | F4: Descripción del hallazgo | G4: Dato documento A | H4: Dato documento B | I4: Norma / referencia | J4: Criticidad | K4: Valor no sustentado est. (COP) | L4: Acción exigida al contratista | M4: Responsable | N4: Fecha límite | O4: Estado | P4: Fecha de cierre | Q4: Respuesta / evidencia de cierre | R4: Observaciones interventoría
A5: OBS-001 | B5: Documentación | C5: Planos 01 y 02 (Stand Iluminaciones) | D5: Rótulo de planos | E5: Incumplimiento normativo | F5: Los planos de iluminación no tienen firma del diseñador ni matrícula profesional. Son un diseño comercial del proveedor y traen la nota "revalidar el diseño antes de la orden de pedido". | G5: Firma del diseñador: vacía | H5: Nota: revalidar antes de pedido | I5: RETIE vigente: diseño por profesional competente con matrícula | J5: Alta | L5: Presentar diseño y memoria firmados por ingeniero electricista con matrícula profesional vigente, con revalidación del diseño. | O5: Abierta
A6: OBS-002 | B6: Documentación | C6: Planos 01/02, informe DIALux, Excel acta | D6: Fecha de planos | E6: Verificar | F6: Planos e informe tienen fecha 23-09-2026, tres días antes de la terminación contractual (26-09-2026). Hay que aclarar si el diseño se aprobó antes de comprar o instalar. | G6: Planos: 23-09-2026 | H6: Terminación contractual: 26-09-2026 | I6: Contrato 1376-2025 / procedimiento de modificaciones | J6: Media | L6: Aportar acta o aprobación de la interventoría y del IDER que respalde la adopción del diseño y la fecha de aprobación. | O6: Abierta
A7: OBS-003 | B7: Documentación | C7: Informe DIALux | D7: Cancha de Fútbol 9 | E7: Información faltante | F7: No se presentó el informe de iluminación de la cancha de Fútbol 9 (32 × 480 W, 4 mástiles de 22 m). | G7: Informe presentado: solo Múltiple | H7: Plano 01: Fútbol 9 | I7: RETILAP vigente | J7: Alta | L7: Presentar informe DIALux de Fútbol 9 con posiciones, alturas, orientación, Em, uniformidad y deslumbramiento. | O7: Abierta
A8: OBS-004 | B8: Documentación | C8: Unifilar, cálculo, Excel | D8: Cancha de Fútbol 6 | E8: Información faltante | F8: Existe circuito en unifilar y alimentador en el balance (IN14.10), pero no hay plano ni informe de iluminación de Fútbol 6. | G8: Unifilar: circuito Fútbol 6 (≈1,7 kW) | H8: Planos: ninguno | I8: RETILAP vigente | J8: Alta | L8: Presentar plano e informe de iluminación de Fútbol 6 o aclarar el alcance de esa cancha. | O8: Abierta
A9: OBS-005 | B9: Documentación | C9: Informe DIALux | D9: Fotometría | E9: Información faltante | F9: La luminaria usa fotometría "definida por el usuario". No hay archivos LDT/IES ni informe de laboratorio del modelo exacto. | G9: Informe: "Definido por el usuario" | H9: No se aportó certificado | I9: RETILAP vigente: certificado de conformidad del producto | J9: Media | L9: Entregar LDT/IES, certificados RETILAP y fichas técnicas del modelo instalado. | O9: Abierta
A10: OBS-006 | B10: Documentación | C10: DXF, cálculo | D10: Tableros TB-CM-ADM, TB-GT, TBGCI | E10: Información faltante | F10: Faltan unifilares y cuadros de carga de los tableros de camerinos, garita y GFCI. | G10: DXF: rótulos de tableros | H10: No hay diagramas | I10: NTC 2050 / RETIE vigente: cuadros de carga y protecciones | J10: Media | L10: Presentar unifilares y cuadros de carga de cada tablero. | O10: Abierta
A11: OBS-007 | B11: Iluminación (diseño) | C11: Plano 01, DXF, cálculo, Excel | D11: IN16.18 / Fútbol 9 | E11: Discrepancia | F11: La cantidad coincide (32), pero el balance cobra proyectores de 820 W y el diseño usa 480 W (4G 45°). | G11: Balance: 32 × 820 W | H11: Plano/DXF/cálculo: 32 × 480 W | I11: Contrato / especificaciones técnicas | J11: Alta | K11: =Balance_Cantidades!K5 | L11: Aclarar la referencia a instalar. Si se instala 480 W, ajustar el valor del ítem. Si es 820 W, aportar diseño que lo respalde. | O11: Abierta
A12: OBS-008 | B12: Iluminación (diseño) | C12: Plano 01, DXF, cálculo | D12: Fútbol 9 | E12: Concordancia | F12: 32 proyectores de 480 W en 4 mástiles de 22 m (8 por mástil), 3,84 kW por mástil. Coinciden plano, DXF y cálculo de regulación. | G12: Plano: 32 | H12: DXF: 32; cálculo: 4 × 3.840 W | I12: — | J12: Baja | L12: Sin acción. | O12: No aplica
A13: OBS-009 | B13: Iluminación (diseño) | C13: Excel, plano 01 | D13: IN14.21 | E13: Discrepancia | F13: El ítem dice capacidad para 10 reflectores a igual precio que el 4.47 retirado (capacidad 8). El diseño usa 8 por mástil. | G13: Balance: 10 reflectores | H13: Plano: 8 por mástil | I13: Contrato | J13: Media | L13: Justificar el cambio de capacidad o corregir la descripción y el valor. | O13: Abierta
A14: OBS-010 | B14: Iluminación (diseño) | C14: Plano 01, DXF, cálculo, Excel | D14: IN14.21 / cantidad | E14: Concordancia | F14: Cuatro mástiles de 22 m coinciden entre balance, plano, DXF y cálculo. | G14: Balance: 4 | H14: Plano: 4 | I14: — | J14: Baja | L14: Sin acción. | O14: No aplica
A15: OBS-011 | B15: Iluminación (diseño) | C15: Excel, plano 02, informe DIALux, cálculo | D15: IN16.19 / Múltiple y Fútbol 6 | E15: Discrepancia | F15: El balance incluye 46 proyectores de 450 W. Ningún plano, informe, cálculo ni unifilar los respalda: el plano y el informe muestran 6 × 160 W y el cálculo 18 × 160 W. | G15: Balance: 46 × 450 W (20,7 kW) | H15: Plano/informe: 6 × 160 W (0,92 kW) | I15: Contrato / diseño aprobado | J15: Alta | K15: =Balance_Cantidades!K6 | L15: Presentar el diseño que respalde 46 proyectores de 450 W o retirar el excedente del balance. | O15: Abierta
A16: OBS-012 | B16: Iluminación (diseño) | C16: Excel, plano 02, DXF, cálculo, unifilar | D16: IN14.20 / postes de 12 m | E16: Discrepancia | F16: Postes de 12 m con cuatro cifras distintas: balance 8, tabla del plano 4, dibujados 2 (DXF confirma 2 grupos de 3), cálculo 6 y unifilar 2 circuitos. | G16: Balance: 8 | H16: Plano: 4 (tabla) / 2 (dibujados); cálculo: 6 | I16: Contrato / diseño | J16: Alta | K16: =Balance_Cantidades!K7 | L16: Unificar el número de postes en todos los documentos y ajustar el balance al diseño aprobado. | O16: Abierta
A17: OBS-013 | B17: Iluminación (diseño) | C17: Excel | D17: IN14.20 vs IN16.19 | E17: Discrepancia | F17: El propio balance es inconsistente: 8 postes × 4 reflectores = 32 de capacidad, pero se compran 46 proyectores. | G17: Capacidad: 32 | H17: Compra: 46 | I17: Coherencia interna del balance | J17: Media | L17: Corregir cantidades o capacidad. | O17: Abierta
A18: OBS-014 | B18: Balance / Actas | C18: Excel | D18: 4.44 Orientación | E18: Discrepancia | F18: Se pagan 78 orientaciones de proyectores (32 + 46). Criterio de la interventoría: solo corresponden 4, una por mástil de Fútbol (el diseño tiene 38 proyectores). | G18: Balance: 78 | H18: Interventoría: 4 | I18: Contrato | J18: Media | K18: =Balance_Cantidades!K11 | L18: Ajustar cantidad de orientaciones. | O18: Abierta
A19: OBS-015 | B19: Balance / Actas | C19: Excel, plano | D19: 4.29 Apantallamiento | E19: Discrepancia | F19: El balance pasa a 10 sistemas de apantallamiento, pero hay 8 postes/mástiles según plano (6 si se cuentan solo 2 postes del múltiple). | G19: Balance: 10 | H19: Plano: 8 | I19: RETIE vigente: evaluación de riesgo por rayos | J19: Media | K19: =Balance_Cantidades!K12 | L19: Justificar con evaluación de riesgo por rayos y número real de postes. | O19: Abierta
A20: OBS-016 | B20: Balance / Actas | C20: Excel, plano | D20: 4.25 Cajas de abonado | E20: Discrepancia | F20: El acta pasa de 4 a 10 cajas de abonado. Criterio de la interventoría: deberían ser 12 (4 mástiles + 8 postes). Quedan 2 por debajo. | G20: Balance: 10 | H20: Interventoría: 12 | I20: Contrato | J20: Baja | K20: =Balance_Cantidades!K13 | L20: Ajustar a 12 si se confirman 8 postes de 12 m; de lo contrario, conciliar con el plano. | O20: Abierta
A21: OBS-017 | B21: Balance / Actas | C21: Excel | D21: Luminaria solar 60 W (sin código) | E21: Discrepancia | F21: Se incluyen 30 luminarias solares sin ítem de contrato, sin plano ni diseño, con unidad "UMD". | G21: Balance: 30 | H21: Planos: 0 | I21: Contrato / procedimiento de ítems nuevos | J21: Alta | K21: =Balance_Cantidades!K9 | L21: Presentar diseño, ubicación y análisis de precios, o retirar el ítem. | O21: Abierta
A22: OBS-018 | B22: Balance / Actas | C22: Excel | D22: Poste solar 5 m (sin código) | E22: Discrepancia | F22: Se incluyen 30 postes metálicos de 5 m para luminarias solares sin diseño que los respalde. | G22: Balance: 30 | H22: Planos: 0 | I22: Contrato | J22: Alta | K22: =Balance_Cantidades!K10 | L22: Igual que el ítem anterior. | O22: Abierta
A23: OBS-019 | B23: Balance / Actas | C23: Excel | D23: Celda J313 | E23: Discrepancia | F23: La celda J313 (=J308+J307) suma solo los mástiles ($446,1 M) y se presenta como subtotal. No es el total de IN14. | G23: J313 = 446.074.546 | H23: Suma de líneas IN14 ≈ 1.701 M | I23: Control de acta | J23: Media | L23: Corregir las fórmulas y presentar un subtotal de IN14 que incluya todas las líneas. | O23: Abierta
A24: OBS-020 | B24: Balance / Actas | C24: Excel | D24: Numeración y unidades | E24: Discrepancia | F24: IN16.18 e IN16.19 deberían ser IN14.18 e IN14.19. IN14.11 no tiene unidad, IN14.19 tiene la unidad en otra columna, hay un 817,2 suelto en la fila 292 y ítems sin código. | G24: IN16.x | H24: IN14.x | I24: Control de acta | J24: Baja | L24: Corregir codificación y formato del acta. | O24: Abierta
A25: OBS-021 | B25: Balance / Actas | C25: DXF, Excel | D25: Postes existentes de 11 m | E25: Verificar | F25: El DXF muestra 6 postes existentes de 11 m con cruceta. El ítem 1.4 (desmonte de postes eléctricos) pasa de 9 a 0. | G25: DXF: 6 existentes | H25: Balance 1.4: 0 | I25: Contrato | J25: Media | L25: Aclarar qué postes se retiran y cuáles se conservan. | O25: Abierta
A26: OBS-022 | B26: Iluminación (diseño) | C26: Plano 02, informe DIALux | D26: Cancha Múltiple | E26: Concordancia | F26: 6 luminarias de 160 W (153,3 W reales; 919,5 W en total) coinciden entre plano e informe. | G26: Plano: 6 × 160 W | H26: Informe: 6 × 153,3 W | I26: — | J26: Baja | L26: Sin acción. | O26: No aplica
A27: OBS-023 | B27: Iluminación (diseño) | C27: Informe DIALux | D27: Múltiple – resultados | E27: Verificar | F27: Em = 128 lx, Emin = 63 lx, Emin/Em = 0,49. Cumple un nivel recreativo (referencia EN 12193 Clase III), pero no la Clase II (200 lx, 0,5). | G27: Em 128 lx | H27: Requisito del contrato / RETILAP | I27: RETILAP vigente: tabla de baloncesto y múltiple | J27: Media | L27: Confirmar la categoría exigida por el contrato y demostrar su cumplimiento. | O27: Abierta
A28: OBS-024 | B28: Iluminación (diseño) | C28: Informe DIALux | D28: Isolíneas página 8 | E28: Discrepancia | F28: La distribución es desigual: 180 lx en el centro y 90 lx o menos bajo los aros. Los dos postes están en el centro de las bandas laterales. | G28: Máx. 204 lx | H28: Mín. 63 lx bajo los aros | I28: RETILAP vigente | J28: Media | L28: Optimizar ubicación u orientación o justificar el nivel en zonas de juego. | O28: Abierta
A29: OBS-025 | B29: Iluminación (diseño) | C29: Informe DIALux | D29: Datos de planificación | E29: Información faltante | F29: El informe no da posición, altura, inclinación ni orientación de las luminarias. El factor de mantenimiento 0,90 es optimista para exterior y no está justificado. | G29: Mf = 0,90 | H29: Sin tabla de montaje | I29: RETILAP vigente | J29: Media | L29: Completar el informe con tabla de montaje y justificación del factor de mantenimiento. | O29: Abierta
A30: OBS-026 | B30: Iluminación (diseño) | C30: Informe DIALux, plano 02 | D30: Designación | E30: Verificar | F30: El informe nombra "Exterior High Bay IP66 3-G 160W 60°" y el plano "Proyector STIL LED 3G (2 módulos) 160W". Confirmar que es el mismo producto certificado. | G30: Informe: High Bay | H30: Plano: Proyector | I30: RETILAP vigente: certificación del producto | J30: Baja | L30: Aclarar con ficha técnica y certificado. | O30: Abierta
A31: OBS-027 | B31: Cálculo de regulación | C31: Cuadro de regulación | D31: Fórmula ΔV | E31: Incumplimiento normativo | F31: La fórmula usa conductividad γ = 56 (cobre) para cables de aluminio S8000 (γ ≈ 35). Las caídas están subestimadas entre un 60 y un 65 %. | G31: Hoja: γ = 56 | H31: Aluminio: γ ≈ 35 | I31: NTC 2050 Cap. 9 Tabla 9 (resistencia de conductores) | J31: Alta | L31: Recalcular con resistencia del aluminio (incluyendo reactancia) y reemitir el cuadro de regulación. | O31: Abierta
A32: OBS-028 | B32: Cálculo de regulación | C32: Cuadro de regulación | D32: Mástil 1 | E32: Incumplimiento normativo | F32: Se usa S = 68 mm² para el #4 Al (real 21,14 mm²). Recalculado: 4,18 % en el alimentador, frente al 0,81 % reportado y por encima del 3 %. | G32: Hoja: 0,81 % | H32: Recalculado: 4,18 % | I32: NTC 2050 210-19 y 215-2 (3 % / 5 %) | J32: Alta | L32: Aumentar calibre (≥ #2 Al) o reubicar el tablero, y recalcular. | O32: Abierta
A33: OBS-029 | B33: Cálculo de regulación | C33: Cuadro de regulación | D33: Mástil 2 | E33: Incumplimiento normativo | F33: Recalculado con γ de aluminio: 3,44 % (hoja: 2,15 %), por encima del 3 %. | G33: Hoja: 2,15 % | H33: Recalculado: 3,44 % | I33: NTC 2050 210-19 y 215-2 | J33: Alta | L33: Igual que Mástil 1. | O33: Abierta
A34: OBS-030 | B34: Cálculo de regulación | C34: Cuadro de regulación | D34: Transformador (350 MCM) | E34: Discrepancia | F34: Se usa 202 mm² para 350 MCM (la tabla de la misma hoja da 177,34 mm²). Efecto menor (tramo de 15 m). | G34: Hoja: 202 mm² | H34: Tabla: 177,34 mm² | I34: NTC 2050 Cap. 9 | J34: Baja | L34: Corregir la sección. | O34: Abierta
... A39: OBS-035 | B39: Tableros y protecciones | C39: Cuadro de regulación, unifilar | D39: TB-Camerinos | E39: Incumplimiento normativo | F39: La corriente calculada es 40,4 A y la protección es 2 × 40 A: la protección queda por debajo de la corriente de carga (125 % en cargas continuas). | G39: I = 40,4 A | H39: Breaker: 40 A | I39: NTC 2050 210-20 y 215-3 | J39: Media | L39: Redimensionar protección y calibre. | O39: Abierta
A40: OBS-036 | B40: Cálculo de regulación | C40: Excel, cálculo | D40: IN14.11 alimentador mástiles | E40: Discrepancia | F40: El balance cobra 817,2 m y el cálculo da 673 m (incluye altura). El DXF mide unos 576 m (BT-05 sin trazado). | G40: Balance: 817,2 m | H40: Cálculo: 673 m | I40: Contrato | J40: Media | K40: =Balance_Cantidades!K14 | L40: Presentar plano de recorridos con metrajes por circuito. | O40: Abierta
A41: OBS-037 | B41: Cálculo de regulación | C41: Excel, cálculo, DXF | D41: IN14.10 alimentador canchas | E41: Discrepancia | F41: El balance cobra 486,8 m y el cálculo da 408 m (el DXF solo muestra unos 196 m). | G41: Balance: 486,8 m | H41: Cálculo: 408 m | I41: Contrato | J41: Media | K41: =Balance_Cantidades!K15 | L41: Presentar recorridos con metrajes por circuito. | O41: Abierta
A42: OBS-038 | B42: Cálculo de regulación | C42: Excel, cálculo | D42: IN14.7 / IN14.8 / IN14.9 | E42: Discrepancia | F42: Longitudes de acometidas distintas entre balance y cálculo: transformador–TGD 27,6 vs 15 m, garita 64,8 vs 58 m, camerinos 4,8 vs 8 m. | G42: Balance: 27,6 / 64,8 / 4,8 m | H42: Cálculo: 15 / 58 / 8 m | I42: Contrato | J42: Baja | K42: =Balance_Cantidades!K16+Balance_Cantidades!K17 | L42: Conciliar longitudes con el plano de recorridos. | O42: Abierta
A43: OBS-039 | B43: Unifilar / MT / Medida | C43: Unifilar | D43: Punto de conexión | E43: Información faltante | F43: El punto de conexión de Afinia figura con tramo, circuito y subestación "PENDIENTE". | G43: Unifilar: PENDIENTE | H43: Ítem 4.1 se mantiene | I43: Requisitos del operador de red | J43: Alta | L43: Entregar la factibilidad aprobada con el punto de conexión definido. | O43: Abierta
A44: OBS-040 | B44: Unifilar / MT / Medida | C44: Unifilar, Excel | D44: Transformador 50 kVA | E44: Discrepancia | F44: El unifilar muestra transformador tipo poste de 50 kVA. El 4.9 (100 kVA) se retiró y no hay ítem de reemplazo. | G44: Unifilar: 50 kVA | H44: Balance: 0 | I44: Contrato | J44: Alta | K44: =Balance_Cantidades!K20 | L44: Aclarar quién suministra el transformador y, si lo hace el contratista, incluir el ítem. | O44: Abierta
A45: OBS-041 | B45: Unifilar / MT / Medida | C45: Unifilar, Excel | D45: Poste EPP007 | E45: Discrepancia | F45: El unifilar tiene un segundo apoyo (EPP007) para el transformador. El ítem 4.5 de poste de concreto se retiró. | G45: Unifilar: EPP007 | H45: Balance: 0 | I45: Contrato | J45: Media | K45: =Balance_Cantidades!K21 | L45: Aclarar el apoyo y su ítem. | O45: Abierta
...

Sheet Lista_Verificacion
D1: Lista de verificación para revisión eléctrica de proyectos
D2: Formato reutilizable. Diligenciar Resultado y, si no cumple, abrir observación en la matriz. Las referencias son de orden general: completar el numeral aplicable.
A4: # | B4: Sección | C4: Requisito a verificar | D4: Referencia | E4: Resultado | F4: Observación / ID matriz
A5: 1 | B5: Documentación | C5: Planos y memorias firmados por profesional con matrícula vigente | D5: RETIE vigente | E5: Pendiente
A6: 2 | B6: Documentación | C6: Fechas y versión del diseño coherentes con la ejecución y el contrato | D6: Contrato | E6: Pendiente
A7: 3 | B7: Documentación | C7: Factibilidad / punto de conexión definido y aprobado por el operador de red | D7: Operador de red | E7: Pendiente
A8: 4 | B8: Documentación | C8: Planos, cálculos, unifilar y balance con las mismas cantidades | D8: Coherencia de diseño | E8: Pendiente
A9: 5 | B9: Documentación | C9: Certificados de producto (luminarias, cables, tableros, DPS, transformador) | D9: RETIE vigente; RETILAP vigente | E9: Pendiente
A10: 6 | B10: Documentación | C10: Archivos fotométricos (LDT/IES) y fichas técnicas | D10: RETILAP vigente | E10: Pendiente
A11: 7 | B11: Media tensión y medida | C11: Conductor, apoyos y vanos acotados y coherentes con el balance | D11: Operador de red | E11: Pendiente
A12: 8 | B12: Media tensión y medida | C12: Protecciones de MT (cortacircuitos, fusibles, DPS) seleccionadas por corriente nominal | D12: RETIE vigente; operador de red | E12: Pendiente
A13: 9 | B13: Media tensión y medida | C13: Esquema de medida (TC, TP, medidor) conforme a lo requerido por el operador | D13: Operador de red | E13: Pendiente
A14: 10 | B14: Transformador | C14: Potencia del transformador sustentada con cuadro de cargas y demanda | D14: NTC 2050; RETIE vigente | E14: Pendiente
A15: 11 | B15: Transformador | C15: Transformador e ítems asociados presentes en el balance | D15: Control de acta | E15: Pendiente
A16: 12 | B16: Tableros y protecciones | C16: Protecciones ≥ 125 % de la carga continua y ≤ ampacidad del conductor | D16: NTC 2050 210-20 y 215-3 | E16: Pendiente
... A38: 34 | B38: Balance | C38: Fórmulas y subtotales del acta correctos | D38: Control de acta | E38: Pendiente

Sheet Formato_Blanco
D1: Matriz de observaciones – formato en blanco
D2: Copiar esta hoja para cada nuevo proyecto. Listas desplegables y formato condicional ya aplicados.
A4: ID | B4: Área | C4: Documento(s) fuente | D4: Ref. (ítem / plano / hoja) | E4: Tipo | F4: Descripción del hallazgo | G4: Dato documento A | H4: Dato documento B | I4: Norma / referencia | J4: Criticidad | K4: Valor no sustentado est. (COP) | L4: Acción exigida al contratista | M4: Responsable | N4: Fecha límite | O4: Estado | P4: Fecha de cierre | Q4: Respuesta / evidencia de cierre | R4: Observaciones interventoría
A5: =IF(F5="","","OBS-"&TEXT(ROW()-4,"000"))
A6: =IF(F6="","","OBS-"&TEXT(ROW()-4,"000"))
A7: =IF(F7="","","OBS-"&TEXT(ROW()-4,"000"))
A8: =IF(F8="","","OBS-"&TEXT(ROW()-4,"000"))
A9: =IF(F9="","","OBS-"&TEXT(ROW()-4,"000"))
A10: =IF(F10="","","OBS-"&TEXT(ROW()-4,"000"))
A11: =IF(F11="","","OBS-"&TEXT(ROW()-4,"000"))
A12: =IF(F12="","","OBS-"&TEXT(ROW()-4,"000"))
A13: =IF(F13="","","OBS-"&TEXT(ROW()-4,"000"))
A14: =IF(F14="","","OBS-"&TEXT(ROW()-4,"000"))
A15: =IF(F15="","","OBS-"&TEXT(ROW()-4,"000"))
A16: =IF(F16="","","OBS-"&TEXT(ROW()-4,"000"))
... A204: =IF(F204="","","OBS-"&TEXT(ROW()-4,"000"))

Sheet Documentos
D1: Documentos revisados y documentos pendientes
D2: Control de entregas del contratista.
A4: # | B4: Documento | C4: Archivo / origen | D4: Estado | E4: Observación
A5: 1 | B5: Acta de mayores y menores cantidades e ítems nuevos – hoja 1 (corte 15-10-26) | C5: ACT ELECTRICO 15-10-26.xlsx | D5: Revisado | E5: Cap. 4 e IN14.
A6: 2 | B6: Plano 01 – Iluminación Cancha de Fútbol 9 (V2) | C6: 26HO068 … FUTBOL 9 – PLANO 01.pdf | D6: Revisado | E6: Sin firma del diseñador.
A7: 3 | B7: Plano 02 – Iluminación Cancha Múltiple (V2) | C7: 26HO068 … MULTIPLE – PLANO 02.pdf | D7: Revisado | E7: Recibido dos veces (idéntico).
A8: 4 | B8: Informe DIALux – Cancha Múltiple (V2) | C8: 26HO068 … MULTIPLE – V2 Informe.pdf | D8: Revisado | E8: Fotometría definida por el usuario.
A9: 5 | B9: DXF de redes eléctricas (Dibujo1) | C9: Dibujo1.dxf | D9: Revisado | E9: Metrajes por polilíneas, incompletos (BT-05).
A10: 6 | B10: Cuadros de carga y cálculos eléctricos (regulación y ductería) | C10: Cuadros de Carga y Calculos Electricos.xlsx | D10: Revisado | E10: Errores de fórmula (γ y secciones).
A11: 7 | B11: Diagrama unifilar | C11: Doc1.docx (imágenes) | D11: Revisado | E11: Rótulos de carga borrosos; falta fuente editable.
A12: 8 | B12: Informe DIALux – Cancha de Fútbol 9 | C12: — | D12: Pendiente | E12: Solicitar.
A13: 9 | B13: Plano e informe de iluminación – Cancha de Fútbol 6 | C13: — | D13: Pendiente | E13: Solicitar o aclarar alcance.
A14: 10 | B14: Archivos fotométricos LDT/IES y certificados de producto | C14: — | D14: Pendiente | E14: Solicitar.
A15: 11 | B15: Unifilares y cuadros de carga de TB-CM-ADM, TB-GT y TBGCI | C15: — | D15: Pendiente | E15: Solicitar.
A16: 12 | B16: Factibilidad / punto de conexión del operador de red | C16: — | D16: Pendiente | E16: Unifilar indica PENDIENTE.
... A18: 14 | B18: Diseño y justificación de luminarias y postes solares | C18: — | D18: Pendiente | E18: Sin respaldo en planos.

Sheet Listas
A1: Tipo | B1: Criticidad | C1: Estado | D1: Area | E1: Resultado | F1: EstadoItem
A2: Concordancia | B2: Alta | C2: Abierta | D2: Documentación | E2: Cumple | F2: Concuerda
A3: Discrepancia | B3: Media | C3: Respondida | D3: Balance / Actas | E3: No cumple | F3: Discrepa
A4: Incumplimiento normativo | B4: Baja | C4: En revisión | D4: Iluminación (diseño) | E4: Parcial | F4: Sin respaldo
A5: Información faltante | C5: Cerrada | D5: Cálculo de regulación | E5: No aplica | F5: Verificar
A6: Verificar | C6: No aplica | D6: Unifilar / MT / Medida | E6: Pendiente | F6: Ítem faltante
D7: Tableros y protecciones | F7: Retirado / reemplazado
D8: Ductería y redes
D9: Puesta a tierra
D10: Otros
